<?xml version="1.0" ?>
<robot name="pr2_l_gripper">

  <!-- materials for visualization -->
  <material name="Blue">
    <color rgba="0.0 0.0 0.8 1.0"/>
  </material>
  <material name="Green">
    <color rgba="0.0 0.8 0.0 1.0"/>
  </material>
  <material name="Grey">
    <color rgba="0.7 0.7 0.7 1.0"/>
  </material>
  <material name="Grey2">
    <color rgba="0.9 0.9 0.9 1.0"/>
  </material>
  <material name="Red">
    <color rgba="0.8 0.0 0.0 1.0"/>
  </material>
  <material name="White">
    <color rgba="1.0 1.0 1.0 1.0"/>
  </material>
  <material name="Black">
    <color rgba="0.1 0.1 0.1 1.0"/>
  </material>
  <material name="LightGrey">
    <color rgba="0.6 0.6 0.6 1.0"/>
  </material>
  <material name="Caster">
    <texture filename="materials/textures/pr2_caster_texture.png"/>
  </material>
  <material name="Wheel_l">
    <texture filename="materials/textures/pr2_wheel_left.png"/>
  </material>
  <material name="Wheel_r">
    <texture filename="materials/textures/pr2_wheel_right.png"/>
  </material>
  <material name="RollLinks">
    <texture filename="materials/textures/pr2_wheel_left.png"/>
  </material>

  <link name="l_gripper_palm_link">
    <inertial>
      <mass value="0.58007"/>
      <origin rpy="0 0 0" xyz="0.06623 0.00053 -0.00119"/>
      <inertia ixx="0.00035223921" ixy="-0.00001580476" ixz="-0.00000091750" iyy="0.00067741312" iyz="-0.00000059554" izz="0.00086563316"/>
    </inertial>
    <visual>
      <origin rpy="0 0 0" xyz="0 0 0"/>
      <geometry>
        <mesh filename="meshes/gripper_v0/gripper_palm.dae"/>
      </geometry>
      <material name="Red"/>
    </visual>
    <collision>
      <origin rpy="0 0 0" xyz="0 0 0"/>
      <geometry>
        <mesh filename="meshes/gripper_v0/gripper_palm.stl"/>
      </geometry>
    </collision>
  </link>
  <joint name="l_gripper_led_joint" type="fixed">
    <!--  Need to check if we need a positive or negative Z term -->
    <origin xyz="0.0513 0.0 .0244"/>
    <parent link="l_gripper_palm_link"/>
    <child link="l_gripper_led_frame"/>
  </joint>
  <link name="l_gripper_led_frame">
    <inertial>
      <mass value="0.01"/>
      <origin xyz="0 0 0"/>
      <inertia ixx="0.001" ixy="0.0" ixz="0.0" iyy="0.001" iyz="0.0" izz="0.001"/>
    </inertial>
  </link>
  <joint name="l_gripper_motor_accelerometer_joint" type="fixed">
    <origin rpy="0 0 0" xyz="0 0 0"/>
    <parent link="l_gripper_palm_link"/>
    <child link="l_gripper_motor_accelerometer_link"/>
  </joint>
  <link name="l_gripper_motor_accelerometer_link">
    <inertial>
      <mass value="0.001"/>
      <origin rpy="0 0 0" xyz="0 0 0"/>
      <inertia ixx="0.001" ixy="0.0" ixz="0.0" iyy="0.001" iyz="0.0" izz="0.001"/>
    </inertial>
    <visual>
      <origin rpy="0 0 0" xyz="0 0 0"/>
      <geometry>
        <box size="0.001 0.001 0.001"/>
      </geometry>
    </visual>
    <collision>
      <origin rpy="0 0 0" xyz="0 0 0"/>
      <geometry>
        <box size="0.001 0.001 0.001"/>
      </geometry>
    </collision>
  </link>
  <joint name="l_gripper_tool_joint" type="fixed">
    <origin rpy="0 0 0" xyz="0.18 0 0"/>
    <parent link="l_gripper_palm_link"/>
    <child link="l_gripper_tool_frame"/>
  </joint>
  <link name="l_gripper_tool_frame">
    <inertial>
      <mass value="0.01"/>
      <origin xyz="0 0 0"/>
      <inertia ixx="0.001" ixy="0.0" ixz="0.0" iyy="0.001" iyz="0.0" izz="0.001"/>
    </inertial>
  </link>
  <!-- actuated motor screw joint -->
  <link name="l_gripper_motor_slider_link">
    <inertial>
      <mass value="0.01"/>
      <origin rpy="0 0 0" xyz="0 0 0"/>
      <inertia ixx="0.001" ixy="0.0" ixz="0.0" iyy="0.001" iyz="0.0" izz="0.001"/>
    </inertial>
    <!-- for debugging only
      <visual>
        <origin xyz="0 0 0" rpy="1.5708 0 0" />
        <geometry>
          <cylinder length="0.002" radius="0.025"/>
        </geometry>
      </visual>
      <collision>
        <origin xyz="0 0 0" rpy="1.5708 0 0" />
        <geometry>
          <cylinder length="0.002" radius="0.025"/>
        </geometry>
      </collision>
      -->
  </link>
  <joint name="l_gripper_motor_slider_joint" type="prismatic">
    <origin rpy="0 0 0" xyz="0.16828 0 0"/>
    <axis xyz="1 0 0"/>
    <parent link="l_gripper_palm_link"/>
    <child link="l_gripper_motor_slider_link"/>
    <limit effort="1000.0" lower="-0.1" upper="0.1" velocity="0.2"/>
  </joint>
  <link name="l_gripper_motor_screw_link">
    <inertial>
      <mass value="0.01"/>
      <origin rpy="0 0 0" xyz="0 0 0"/>
      <inertia ixx="0.0001" ixy="0.0" ixz="0.0" iyy="0.0001" iyz="0.0" izz="0.0001"/>
    </inertial>
    <!-- for debugging only
      <visual>
        <origin xyz="0 0 0" rpy="0 0 0" />
        <geometry>
          <box size="0.05 0.001 0.05" />
        </geometry>
      </visual>
      <collision>
        <origin xyz="0 0 0" rpy="0 0 0" />
        <geometry>
          <box size="0.05 0.001 0.05" />
        </geometry>
      </collision>
      -->
  </link>
  <joint name="l_gripper_motor_screw_joint" type="continuous">
    <origin rpy="0 0 0" xyz="0.0 0 0"/>
    <axis xyz="0 1 0"/>
    <parent link="l_gripper_motor_slider_link"/>
    <child link="l_gripper_motor_screw_link"/>
    <dynamics damping="0.0001"/>
  </joint>
  <!-- pr2 fingers macro -->
  <!-- Finger proximal digit -->
  <joint name="l_gripper_l_finger_joint" type="revolute">
    <axis xyz="0 0 1"/>
    <!-- limits on passive finger and finger top joints without
         transmission are not enforced by safety controllers.
         The lower/upper limits and are enforced in PR2 simulation and
         effort and velocity limits are ignored. This is also needed because
         these joints are declared revolute rather than continuous.-->
    <limit effort="1000.0" lower="0.0" upper="0.548" velocity="0.5"/>
    <dynamics damping="0.02"/>
    <origin rpy="0 0 0" xyz="0.07691 0.01 0"/>
    <parent link="l_gripper_palm_link"/>
    <child link="l_gripper_l_finger_link"/>
  </joint>
  <link name="l_gripper_l_finger_link">
    <inertial>
      <mass value="0.17126"/>
      <origin rpy="0 0 0" xyz="0.03598 0.01730 -0.00164"/>
      <inertia ixx="0.00007756198" ixy="0.00000149095" ixz="-0.00000983385" iyy="0.00019708305" iyz="-0.00000306125" izz="0.00018105446"/>
    </inertial>
    <visual>
      <origin rpy="0 0 0" xyz="0 0 0"/>
      <geometry>
        <mesh filename="meshes/gripper_v0/l_finger.dae"/>
      </geometry>
      <material name="Grey"/>
    </visual>
    <collision>
      <origin rpy="0 0 0" xyz="0 0 0"/>
      <geometry>
        <mesh filename="meshes/gripper_v0/l_finger.stl"/>
      </geometry>
    </collision>
  </link>
  <!-- Finger proximal digit -->
  <joint name="l_gripper_r_finger_joint" type="revolute">
    <axis xyz="0 0 -1"/>
    <origin rpy="0 0 0" xyz="0.07691 -0.01 0"/>
    <!-- limits on passive finger and finger top joints without
         transmission are not enforced by safety controllers.
         The lower/upper limits and are enforced in PR2 simulation and
         effort and velocity limits are ignored. This is also needed because
         these joints are declared revolute rather than continuous.-->
    <limit effort="1000.0" lower="0.0" upper="0.548" velocity="0.5"/>
    <dynamics damping="0.02"/>
    <mimic joint="l_gripper_l_finger_joint" multiplier="1" offset="0"/>
    <parent link="l_gripper_palm_link"/>
    <child link="l_gripper_r_finger_link"/>
  </joint>
  <link name="l_gripper_r_finger_link">
    <inertial>
      <mass value="0.17389"/>
      <origin rpy="0 0 0" xyz="0.03576 -0.01736 -0.00095"/>
      <inertia ixx="0.00007738410" ixy="-0.00000209309" ixz="-0.00000836228" iyy="0.00019847383" iyz="0.00000246110" izz="0.00018106988"/>
    </inertial>
    <visual>
      <origin rpy="3.14159265359 0 0" xyz="0 0 0"/>
      <geometry>
        <mesh filename="meshes/gripper_v0/l_finger.dae"/>
      </geometry>
      <material name="Grey"/>
    </visual>
    <collision>
      <origin rpy="3.14159265359 0 0" xyz="0 0 0"/>
      <geometry>
        <mesh filename="meshes/gripper_v0/l_finger.stl"/>
      </geometry>
    </collision>
  </link>
  <!-- Finger tip -->
  <joint name="l_gripper_l_finger_tip_joint" type="revolute">
    <axis xyz="0 0 -1"/>
    <origin rpy="0 0 0" xyz="0.09137 0.00495 0"/>
    <!-- limits on passive finger and finger top joints without
         transmission are not enforced by safety controllers.
         The lower/upper limits and are enforced in PR2 simulation and
         effort and velocity limits are ignored. This is also needed because
         these joints are declared revolute rather than continuous.-->
    <limit effort="1000.0" lower="0.0" upper="0.548" velocity="0.5"/>
    <dynamics damping="0.001"/>
    <mimic joint="l_gripper_l_finger_joint" multiplier="1" offset="0"/>
    <parent link="l_gripper_l_finger_link"/>
    <child link="l_gripper_l_finger_tip_link"/>
  </joint>
  <link name="l_gripper_l_finger_tip_link">
    <inertial>
      <mass value="0.04419"/>
      <origin rpy="0 0 0" xyz="0.00423 0.00284 0.0"/>
      <inertia ixx="0.00000837047" ixy="0.00000583632" ixz="0.0" iyy="0.00000987067" iyz="0.0" izz="0.00001541768"/>
    </inertial>
    <visual>
      <origin rpy="0 0 0" xyz="0 0 0"/>
      <geometry>
        <mesh filename="meshes/gripper_v0/l_finger_tip.dae"/>
      </geometry>
      <material name="Green"/>
    </visual>
    <collision>
      <origin rpy="0 0 0" xyz="0 0 0"/>
      <geometry>
        <mesh filename="meshes/gripper_v0/l_finger_tip.stl"/>
      </geometry>
    </collision>
  </link>
  <!-- Finger tip -->
  <joint name="l_gripper_r_finger_tip_joint" type="revolute">
    <axis xyz="0 0 1"/>
    <origin rpy="0 0 0" xyz="0.09137 -0.00495 0"/>
    <!-- limits on passive finger and finger top joints without
         transmission are not enforced by safety controllers.
         The lower/upper limits and are enforced in PR2 simulation and
         effort and velocity limits are ignored. This is also needed because
         these joints are declared revolute rather than continuous.-->
    <limit effort="1000.0" lower="0.0" upper="0.548" velocity="0.5"/>
    <dynamics damping="0.001"/>
    <mimic joint="l_gripper_l_finger_joint" multiplier="1" offset="0"/>
    <parent link="l_gripper_r_finger_link"/>
    <child link="l_gripper_r_finger_tip_link"/>
  </joint>
  <link name="l_gripper_r_finger_tip_link">
    <inertial>
      <mass value="0.04419"/>
      <origin rpy="0 0 0" xyz="0.00423 -0.00284 0.0"/>
      <inertia ixx="0.00000837047" ixy="-0.00000583632" ixz="0.0" iyy="0.00000987067" iyz="0.0" izz="0.00001541768"/>
    </inertial>
    <visual>
      <origin rpy="3.14159265359 0 0" xyz="0 0 0"/>
      <geometry>
        <mesh filename="meshes/gripper_v0/l_finger_tip.dae"/>
      </geometry>
      <material name="Green"/>
    </visual>
    <collision>
      <origin rpy="3.14159265359 0 0" xyz="0 0 0"/>
      <geometry>
        <mesh filename="meshes/gripper_v0/l_finger_tip.stl"/>
      </geometry>
    </collision>
  </link>
  <!-- extensions -->
  <!-- Finger proximal digit -->
  <gazebo reference="l_gripper_l_finger_link">
    <turnGravityOff>true</turnGravityOff>
    <mu1 value="500.0"/>
    <mu2 value="500.0"/>
    <kp value="1000000.0"/>
    <kd value="1.0"/>
    <!-- for "${prefix}_l_finger_joint"-->
  </gazebo>
  <gazebo reference="l_gripper_l_finger_joint">
    <stopKd value="1.0"/>
    <stopKp value="10000000.0"/>
    <fudgeFactor value="1.0"/>
    <provideFeedback value="true"/>
  </gazebo>
  <!-- Finger proximal digit -->
  <gazebo reference="l_gripper_r_finger_link">
    <turnGravityOff>true</turnGravityOff>
    <mu1 value="500.0"/>
    <mu2 value="500.0"/>
    <kp value="1000000.0"/>
    <kd value="1.0"/>
  </gazebo>
  <gazebo reference="l_gripper_r_finger_joint">
    <stopKd value="1.0"/>
    <stopKp value="10000000.0"/>
    <fudgeFactor value="1.0"/>
    <provideFeedback value="true"/>
  </gazebo>
  <!-- Finger tip -->
  <gazebo reference="l_gripper_l_finger_tip_link">
    <turnGravityOff>true</turnGravityOff>
    <selfCollide>false</selfCollide>
    <sensor name="l_gripper_l_finger_tip_contact_sensor" type="contact">
      <update_rate>100.0</update_rate>
      <contact>
        <collision>l_gripper_l_finger_tip_link_collision</collision>
      </contact>
      <plugin filename="libgazebo_ros_bumper.so" name="l_gripper_l_finger_tip_gazebo_ros_bumper_controller">
        <alwaysOn>true</alwaysOn>
        <frameName>l_gripper_l_finger_tip_link</frameName>
        <updateRate>100.0</updateRate>
        <bumperTopicName>l_gripper_l_finger_tip_bumper</bumperTopicName>
      </plugin>
    </sensor>
    <mu1 value="500.0"/>
    <mu2 value="500.0"/>
    <kp value="10000000.0"/>
    <kd value="1.0"/>
  </gazebo>
  <gazebo reference="l_gripper_l_finger_tip_joint">
    <stopKd value="1.0"/>
    <stopKp value="10000000.0"/>
    <fudgeFactor value="1.0"/>
    <provideFeedback value="true"/>
  </gazebo>
  <!-- Finger tip -->
  <gazebo reference="l_gripper_r_finger_tip_link">
    <turnGravityOff>true</turnGravityOff>
    <selfCollide>false</selfCollide>
    <sensor name="l_gripper_r_finger_tip_contact_sensor" type="contact">
      <update_rate>100.0</update_rate>
      <contact>
        <collision>l_gripper_r_finger_tip_link_collision</collision>
      </contact>
      <plugin filename="libgazebo_ros_bumper.so" name="l_gripper_r_finger_tip_gazebo_ros_bumper_controller">
        <alwaysOn>true</alwaysOn>
        <frameName>l_gripper_r_finger_tip_link</frameName>
        <updateRate>100.0</updateRate>
        <bumperTopicName>l_gripper_r_finger_tip_bumper</bumperTopicName>
      </plugin>
    </sensor>
    <mu1 value="500.0"/>
    <mu2 value="500.0"/>
    <kp value="10000000.0"/>
    <kd value="1.0"/>
  </gazebo>
  <gazebo>
    <plugin filename="libgazebo_ros_p3d.so" name="p3d_l_gripper_l_finger_controller">
      <alwaysOn>true</alwaysOn>
      <updateRate>100.0</updateRate>
      <bodyName>l_gripper_l_finger_link</bodyName>
      <topicName>l_gripper_l_finger_pose_ground_truth</topicName>
      <gaussianNoise>0.0</gaussianNoise>
      <frameName>base_link</frameName>
    </plugin>
    <plugin filename="libgazebo_ros_f3d.so" name="f3d_l_gripper_l_finger_controller">
      <alwaysOn>true</alwaysOn>
      <updateRate>100.0</updateRate>
      <bodyName>l_gripper_l_finger_link</bodyName>
      <topicName>l_gripper_l_finger_force_ground_truth</topicName>
    </plugin>
  </gazebo>
  <gazebo reference="l_gripper_r_finger_tip_joint">
    <stopKd value="1.0"/>
    <stopKp value="10000000.0"/>
    <fudgeFactor value="1.0"/>
    <provideFeedback value="true"/>
  </gazebo>
  <!-- parallel link for simulating gripper constraints -->
  <gazebo>
    <link name="l_gripper_l_parallel_link">
      <inertial>
        <mass>0.17126</mass>
        <inertia>
          <ixx>7.7562e-05</ixx>
          <ixy>1.49095e-06</ixy>
          <ixz>-9.83385e-06</ixz>
          <iyy>0.000197083</iyy>
          <iyz>-3.06125e-06</iyz>
          <izz>0.000181054</izz>
        </inertia>
        <pose>0.03598 0.0173 -0.00164 0 0 0</pose>
      </inertial>
      <pose>0.82991 0.219 0.790675 0 -0 0</pose>
      <gravity>false</gravity>
    </link>
    <link name="l_gripper_r_parallel_link">
      <inertial>
        <mass>0.17389</mass>
        <inertia>
          <ixx>7.73841e-05</ixx>
          <ixy>-2.09309e-06</ixy>
          <ixz>-8.36228e-06</ixz>
          <iyy>0.000198474</iyy>
          <iyz>2.4611e-06</iyz>
          <izz>0.00018107</izz>
        </inertia>
        <pose>0.03576 -0.01736 -0.00095 0 0 0</pose>
      </inertial>
      <pose>0.82991 0.157 0.790675 0 0 0</pose>
      <gravity>false</gravity>
    </link>
  </gazebo>
  <gazebo>
    <joint name="l_gripper_r_screw_screw_joint" type="screw">
      <child>l_gripper_motor_screw_link</child>
      <parent>l_gripper_r_finger_tip_link</parent>
      <thread_pitch>-3141.6</thread_pitch>
      <axis>
        <xyz>0 1 0</xyz>
      </axis>
    </joint>
    <joint name="l_gripper_l_screw_screw_joint" type="screw">
      <parent>l_gripper_l_finger_tip_link</parent>
      <child>l_gripper_motor_screw_link</child>
      <thread_pitch>3141.6</thread_pitch>
      <axis>
        <xyz>0 1 0</xyz>
      </axis>
    </joint>
  </gazebo>
  <gazebo>
    <joint name="l_gripper_r_parallel_root_joint" type="revolute">
      <parent>l_gripper_r_parallel_link</parent>
      <child>l_gripper_palm_link</child>
      <axis>
        <xyz>0 0 -1</xyz>
        <dynamics>
          <damping>0.2</damping>
        </dynamics>
      </axis>
      <pose>0.05891 -0.031 0 0 0 0</pose>
    </joint>
    <joint name="l_gripper_l_parallel_root_joint" type="revolute">
      <parent>l_gripper_l_parallel_link</parent>
      <child>l_gripper_palm_link</child>
      <axis>
        <xyz>0 0 1</xyz>
        <dynamics>
          <damping>0.2</damping>
        </dynamics>
      </axis>
      <pose>0.05891 0.031 0 0 0 0</pose>
    </joint>
    <joint name="l_gripper_r_parallel_tip_joint" type="revolute">
      <parent>l_gripper_r_parallel_link</parent>
      <child>l_gripper_r_finger_tip_link</child>
      <axis>
        <xyz>0 0 1</xyz>
      </axis>
      <pose>-0.018 -0.021 0 0 0 0</pose>
    </joint>
    <joint name="l_gripper_l_parallel_tip_joint" type="revolute">
      <parent>l_gripper_l_parallel_link</parent>
      <child>l_gripper_l_finger_tip_link</child>
      <axis>
        <xyz>0 0 1</xyz>
      </axis>
      <pose>-0.018 0.021 0 0 0 0</pose>
    </joint>
    <joint name="l_gripper_joint" type="prismatic">
      <parent>l_gripper_r_finger_tip_link</parent>
      <child>l_gripper_l_finger_tip_link</child>
      <axis>
        <xyz>0 1 0</xyz>
      </axis>
    </joint>
  </gazebo>
  <gazebo reference="l_gripper_motor_slider_link">
    <turnGravityOff>true</turnGravityOff>
    <material value="PR2/Red"/>
  </gazebo>
  <gazebo reference="l_gripper_motor_screw_link">
    <turnGravityOff>true</turnGravityOff>
    <material value="PR2/Red"/>
  </gazebo>
  <gazebo reference="l_gripper_l_parallel_link">
    <turnGravityOff>true</turnGravityOff>
    <material value="PR2/Red"/>
  </gazebo>
  <gazebo reference="l_gripper_r_parallel_link">
    <turnGravityOff>true</turnGravityOff>
    <material value="PR2/Red"/>
  </gazebo>
  <!-- fictitous joint that represents the gripper gap -->
  <!-- effort is the linear force at the gripper gap
         velocity limit is the linear velocity limit at the gripper gap
         try and introduce a very stiff spring
         The velocity limits are alpha tested.
         The effort limits are somewhat inflated.
         k_velocity was recently raised from 500.0 to 5000.0.  Tested on beta
    -->
  <joint name="l_gripper_joint" type="prismatic">
    <parent link="l_gripper_r_finger_tip_link"/>
    <child link="l_gripper_l_finger_tip_frame"/>
    <axis xyz="0 1 0"/>
    <dynamics damping="10.0"/>
    <limit effort="1000.0" lower="0.0" upper="0.09" velocity="0.2"/>
    <safety_controller k_position="20.0" k_velocity="5000.0" soft_lower_limit="-0.01" soft_upper_limit="0.088"/>
  </joint>
  <!-- This link is the same as the l_finger_tip_link,
	 but because the urdf does not support graph structures,
	 this link exists twice -->
  <link name="l_gripper_l_finger_tip_frame">
    <inertial>
      <mass value="0.01"/>
      <origin xyz="0 0 0"/>
      <inertia ixx="0.001" ixy="0.0" ixz="0.0" iyy="0.001" iyz="0.0" izz="0.001"/>
    </inertial>
  </link>
  <!-- extensions -->
  <gazebo reference="l_gripper_palm_link">
    <turnGravityOff>true</turnGravityOff>
  </gazebo>
  <gazebo>
    <plugin filename="libgazebo_ros_p3d.so" name="p3d_l_gripper_palm_controller">
      <alwaysOn>true</alwaysOn>
      <updateRate>100.0</updateRate>
      <bodyName>l_gripper_palm_link</bodyName>
      <topicName>l_gripper_palm_pose_ground_truth</topicName>
      <xyzOffsets>0 0 0</xyzOffsets>
      <rpyOffsets>0 0 0</rpyOffsets>
      <gaussianNoise>0.0</gaussianNoise>
      <frameName>map</frameName>
    </plugin>
    <!-- a formal implementation of grasp hack in gazebo with fixed joint -->
    <gripper name="l_grasp_hack">
      <grasp_check>
        <attach_steps>20</attach_steps>
        <detach_steps>40</detach_steps>
        <min_contact_count>2</min_contact_count>
      </grasp_check>
      <gripper_link>l_gripper_r_finger_tip_link</gripper_link>
      <gripper_link>l_gripper_l_finger_tip_link</gripper_link>
      <palm_link>l_gripper_palm_link</palm_link>
    </gripper>
  </gazebo>
  <!-- [lr]_gripper_joint is a fictitious joint, used by transmission for controller gap   -->
  <!-- [lr]_gripper_joint is not attached to any link                                      -->
  <!-- [lr]_gripper_joint position is the gap_size                                         -->
  <!-- [lr]_gripper_joint velocity is the gap linear velocity                              -->
  <!-- [lr]_gripper_joint effort   is the gap linear force                                 -->
  <!-- Please refer to function engineering spreadsheet 090224_link_data.xls for           -->
  <!-- the transmission function.                                                          -->
  <!-- Please refer to mechanism_model/src/pr2_gripper_transmission.cpp for implementation.-->
  <!-- gazebo_mimic_pid is for sim only.                                                   -->
  <transmission name="l_gripper_trans" type="pr2_mechanism_model/PR2GripperTransmission">
    <actuator name="l_gripper_motor"/>
    <gap_joint L0="0.0375528" a="0.0683698" b="0.0433849" gear_ratio="40.095" h="0.0" mechanical_reduction="1.0" name="l_gripper_joint" phi0="0.518518122146" r="0.0915" screw_reduction="0.004" t0="-0.0001914" theta0="0.0628824676201"/>
    <!-- if a gazebo joint exists as [l|r]_gripper_joint, use this tag to have
           gripper transmission apply torque directly to prismatic joint
           this should be the default behavior in diamondback, deprecating this flag -->
    <use_simulated_gripper_joint/>
    <!-- set passive joint angles so things look nice in rviz -->
    <passive_joint name="l_gripper_l_finger_joint"/>
    <passive_joint name="l_gripper_r_finger_joint"/>
    <passive_joint name="l_gripper_r_finger_tip_joint"/>
    <passive_joint name="l_gripper_l_finger_tip_joint"/>
    <!-- screw joint to capture gripper "dynamics" -->
    <simulated_actuated_joint name="l_gripper_motor_screw_joint" passive_actuated_joint="l_gripper_motor_slider_joint" simulated_reduction="3141.6"/>
  </transmission>
</robot>
